try {
    throw new Error("에러가 발생하였습니다.");
} catch (e) {

}
console.log("종료되었습니다");